<?xml version="1.0"?>
<robot xmlns:xacro="http://www.ros.org/wiki/xacro" name="black_donut">

    <xacro:include filename="inertial_macros.xacro"/>

    <material name="white">
        <color rgba="1 1 1 1" />
    </material>

    <material name="orange">
        <color rgba="1 0.3 0.1 1"/>
    </material>

    <material name="blue">
        <color rgba="0.2 0.2 1 1"/>
    </material>

    <material name="black">
        <color rgba="0 0 0 1"/>
    </material>

    <!-- BASE_FOOTPRINT LINK -->

    <link name="base_footprint">
    
    </link>

    <!-- BASE LINK -->

    <joint name="base_link_joint" type="fixed">
        <parent link="base_footprint"/>
        <child link="base_link"/>
        <origin xyz="0 0 0"/>
    </joint>

    <link name="base_link">
        <visual>
            <origin xyz="0 0 0.075"/>
            <geometry>
                <cylinder radius="0.2" length="0.2"/>
            </geometry>1
            <material name="black"/>
        </visual>
        <collision>
            <origin xyz="0 0 0.075"/>
            <geometry>
                <box size="0.3 0.3 0.15"/>
            </geometry>
        </collision>
        <xacro:inertial_box mass="0.5" x="0.3" y="0.3" z="0.15">
            <origin xyz="0 0 0.075" rpy="0 0 0"/>
        </xacro:inertial_box>
    </link>

    <!-- TOP PLATE-->
    <joint name="hat_joint" type="fixed">
        <parent link="base_link"/>
        <child link="hat_link"/>
        <origin xyz="0 0 0"/>
    </joint>

    <link name="hat_link">
        <visual>
            <origin xyz="0 0 0.245"/>
            <geometry>
                <cylinder radius="0.2" length="0.01"/>
            </geometry>1
            <material name="black"/>
        </visual>
        <collision>
            <origin xyz="0 0 0.245"/>
            <geometry>
                <box size="0.3 0.3 0.15"/>
            </geometry>
        </collision>
        <xacro:inertial_box mass="0.1" x="0.1" y="0.1" z="0.1">
            <origin xyz="0 0 0.245" rpy="0 0 0"/>
        </xacro:inertial_box>
    </link>
    
    
    <!-- LEFT WHEEL LINK -->

    <joint name="left_wheel_joint" type="continuous">
        <parent link="base_link"/>
        <child link="left_wheel"/>
        <origin xyz="0 0.1 0" rpy="-${pi/2} 0 0" />
        <axis xyz="0 0 1"/>
    </joint>

    <link name="left_wheel">
        <visual>
            <geometry>
                <cylinder radius="0.05" length="0.04"/>
            </geometry>
            <material name="orange"/>
        </visual>
        <collision>
            <geometry>
                <cylinder radius="0.05" length="0.04"/>
            </geometry>
        </collision>
        <xacro:inertial_cylinder mass="0.1" length="0.04" radius="0.05">
            <origin xyz="0 0 0" rpy="0 0 0"/>
        </xacro:inertial_cylinder>
    </link>

    <!-- RIGHT WHEEL LINK -->

    <joint name="right_wheel_joint" type="continuous">
        <parent link="base_link"/>
        <child link="right_wheel"/>
        <origin xyz="0 -0.1 0" rpy="${pi/2} 0 0" />
        <axis xyz="0 0 -1"/>
    </joint>

    <link name="right_wheel">
        <visual>
            <geometry>
                <cylinder radius="0.05" length="0.04"/>
            </geometry>
            <material name="orange"/>
        </visual>
        <collision>
            <geometry>
                <cylinder radius="0.05" length="0.04"/>
            </geometry>
        </collision>
        <xacro:inertial_cylinder mass="0.1" length="0.04" radius="0.05">
            <origin xyz="0 0 0" rpy="0 0 0"/>
        </xacro:inertial_cylinder>
    </link>

    <!-- CASTER WHEEL LINK -->

    <joint name="caster_wheel_f_joint" type="fixed">
        <parent link="base_link"/>
        <child link="caster_wheel_f"/>
        <origin xyz="0.1 0 0"/>
    </joint>


    <link name="caster_wheel_f">
        <visual>
            <geometry>
                <sphere radius="0.05"/>
            </geometry>
            <material name="white"/>
        </visual>
        <collision>
            <geometry>
                <sphere radius="0.05"/>
            </geometry>
        </collision>
        <xacro:inertial_sphere mass="0.1" radius="0.05">
            <origin xyz="0 0 0" rpy="0 0 0"/>
        </xacro:inertial_sphere>
    </link>

    <joint name="caster_wheel_joint_b" type="fixed">
        <parent link="base_link"/>
        <child link="caster_wheel_b"/>
        <origin xyz="-0.1 0 0"/>
    </joint>


    <link name="caster_wheel_b">
        <visual>
            <geometry>
                <sphere radius="0.05"/>
            </geometry>
            <material name="white"/>
        </visual>
        <collision>
            <geometry>
                <sphere radius="0.05"/>
            </geometry>
        </collision>
        <xacro:inertial_sphere mass="0.1" radius="0.05">
            <origin xyz="0 0 0" rpy="0 0 0"/>
        </xacro:inertial_sphere>
    </link>

    <gazebo reference="base_link">
        <material>Gazebo/Black</material>
    </gazebo>

    <gazebo reference="right_wheel">
        <material>Gazebo/Orange</material>
    </gazebo>
    <gazebo reference="left_wheel">
        <material>Gazebo/Orange</material>
    </gazebo>
    <gazebo reference="hat_link">
        <material>Gazebo/Black</material>
        <mu1 value="0.001"/>
        <mu2 value="0.001"/>
    </gazebo>


    <gazebo reference="caster_wheel_f">
        <material>Gazebo/Black</material>
        <mu1 value="0.001"/>
        <mu2 value="0.001"/>
    </gazebo>
    <gazebo reference="caster_wheel_b">
        <material>Gazebo/Black</material>
        <mu1 value="0.001"/>
        <mu2 value="0.001"/>
    </gazebo>
    
    
</robot>