<?xml version="1.0" encoding="utf-8"?>
<!-- This URDF was automatically created by SolidWorks to URDF Exporter! Originally created by Stephen Brawner (brawner@gmail.com) 
     Commit Version: 1.6.0-1-g15f4949  Build Version: 1.6.7594.29634
     For more information, please see http://wiki.ros.org/sw_urdf_exporter -->
<robot
  name="rom2109">
  <link
    name="base_link">
    <inertial>
      <origin
        xyz="0.0020289 0.0006482 0.0064293"
        rpy="0 0 0" />
      <mass
        value="2.3323" />
      <inertia
        ixx="0.010807"
        ixy="5.4399E-06"
        ixz="2.5167E-07"
        iyy="0.013849"
        iyz="-7.22E-06"
        izz="0.024355" />
    </inertial>
    <visual>
      <origin
        xyz="0 0 0"
        rpy="0 0 0" />
      <geometry>
        <mesh
          filename="package://rom2109_description/meshes/short/base_link.STL" />
      </geometry>
      <material
        name="">
        <color
          rgba="0 0 0 1" />
      </material>
    </visual>
    <collision>
      <origin
        xyz="0 0 0"
        rpy="0 0 0" />
      <geometry>
        <mesh
          filename="package://rom2109_description/meshes/short/base_link.STL" />
      </geometry>
    </collision>
  </link>
  <link
    name="right_wheel">
    <inertial>
      <origin
        xyz="5.2042E-18 -0.0009488 -5.5511E-17"
        rpy="0 0 0" />
      <mass
        value="2.8826" />
      <inertia
        ixx="0.0029015"
        ixy="8.8633E-19"
        ixz="1.3928E-19"
        iyy="0.00525"
        iyz="8.1358E-18"
        izz="0.0029015" />
    </inertial>
    <visual>
      <origin
        xyz="0 0 0"
        rpy="0 0 0" />
      <geometry>
        <mesh
          filename="package://rom2109_description/meshes/short/right_wheel.STL" />
      </geometry>
      <material
        name="">
        <color
          rgba="0.79608 0.82353 0.93725 1" />
      </material>
    </visual>
    <collision>
      <origin
        xyz="0 0 0"
        rpy="0 0 0" />
      <geometry>
        <mesh
          filename="package://rom2109_description/meshes/short/right_wheel.STL" />
      </geometry>
    </collision>
  </link>
  <joint
    name="right_wheel_joint"
    type="continuous">
    <origin
      xyz="0 -0.098333 0.02605"
      rpy="0 0 0" />
    <parent
      link="base_link" />
    <child
      link="right_wheel" />
    <axis
      xyz="0 1 0" />
  </joint>
  <link
    name="left_wheel">
    <inertial>
      <origin
        xyz="1.70257904996696E-13 0.000948803305975882 5.8564264548977E-14"
        rpy="0 0 0" />
      <mass
        value="2.88257784807586" />
      <inertia
        ixx="0.00290151800584147"
        ixy="-9.17143280659263E-15"
        ixz="6.05064531282138E-15"
        iyy="0.00524996334354857"
        iyz="-2.70785797323357E-15"
        izz="0.00290151800582675" />
    </inertial>
    <visual>
      <origin
        xyz="0 0 0"
        rpy="0 0 0" />
      <geometry>
        <mesh
          filename="package://rom2109_description/meshes/short/left_wheel.STL" />
      </geometry>
      <material
        name="">
        <color
          rgba="0.796078431372549 0.823529411764706 0.937254901960784 1" />
      </material>
    </visual>
    <collision>
      <origin
        xyz="0 0 0"
        rpy="0 0 0" />
      <geometry>
        <mesh
          filename="package://rom2109_description/meshes/short/left_wheel.STL" />
      </geometry>
    </collision>
  </link>
  <joint
    name="left_wheel_joint"
    type="continuous">
    <origin
      xyz="0 0.098332880094503 0.0260500000000002"
      rpy="0 0 0" />
    <parent
      link="base_link" />
    <child
      link="left_wheel" />
    <axis
      xyz="0 1 0" />
  </joint>
  <link
    name="plate1">
    <inertial>
      <origin
        xyz="0.00237736961809826 -0.00318479486350618 0.00377691255231566"
        rpy="0 0 0" />
      <mass
        value="0.376303345586596" />
      <inertia
        ixx="0.00140681231884876"
        ixy="3.65375356586576E-05"
        ixz="1.4886526756259E-17"
        iyy="0.00141154373447315"
        iyz="-5.38461714563585E-18"
        izz="0.00281452124473489" />
    </inertial>
    <visual>
      <origin
        xyz="0 0 0"
        rpy="0 0 0" />
      <geometry>
        <mesh
          filename="package://rom2109_description/meshes/short/plate1.STL" />
      </geometry>
      <material
        name="">
        <color
          rgba="1 1 0 1" />
      </material>
    </visual>
    <collision>
      <origin
        xyz="0 0 0"
        rpy="0 0 0" />
      <geometry>
        <mesh
          filename="package://rom2109_description/meshes/short/plate1.STL" />
      </geometry>
    </collision>
  </link>
  <joint
    name="plate1_joint"
    type="fixed">
    <origin
      xyz="-0.0038733 0 0.13505"
      rpy="0 0 0" />
    <parent
      link="base_link" />
    <child
      link="plate1" />
    <axis
      xyz="0 0 0" />
  </joint>
  <link
    name="camera">
    <inertial>
      <origin
        xyz="-0.013048 -0.0002462 6.0567E-05"
        rpy="0 0 0" />
      <mass
        value="0.044752" />
      <inertia
        ixx="2.7278E-05"
        ixy="-2.4434E-07"
        ixz="1.174E-09"
        iyy="3.9447E-06"
        iyz="-2.8014E-09"
        izz="2.7362E-05" />
    </inertial>
    <visual>
      <origin
        xyz="0 0 0"
        rpy="0 0 0" />
      <geometry>
        <mesh
          filename="package://rom2109_description/meshes/short/camera.STL" />
      </geometry>
      <material
        name="">
        <color
          rgba="0.79216 0.81961 0.93333 1" />
      </material>
    </visual>
    <collision>
      <origin
        xyz="0 0 0"
        rpy="0 0 0" />
      <geometry>
        <mesh
          filename="package://rom2109_description/meshes/short/camera.STL" />
      </geometry>
    </collision>
  </link>
  <joint
    name="camera_joint"
    type="fixed">
    <origin
      xyz="0.1095 0.00557736269756123 -0.0125000000000011"
      rpy="0 0 0" />
    <parent
      link="plate1" />
    <child
      link="camera" />
    <axis
      xyz="0 0 0" />
  </joint>
  <link
    name="lidar">
    <inertial>
      <origin
        xyz="-0.0074503 -0.00071018 0.010668"
        rpy="0 0 0" />
      <mass
        value="1.3308" />
      <inertia
        ixx="0.00061741"
        ixy="-2.9275E-05"
        ixz="0.00015796"
        iyy="0.0009582"
        iyz="9.999E-06"
        izz="0.0010982" />
    </inertial>
    <visual>
      <origin
        xyz="0 0 0"
        rpy="0 0 0" />
      <geometry>
        <mesh
          filename="package://rom2109_description/meshes/short/lidar.STL" />
      </geometry>
      <material
        name="">
        <color
          rgba="0.79216 0.81961 0.93333 1" />
      </material>
    </visual>
    <collision>
      <origin
        xyz="0 0 0"
        rpy="0 0 0" />
      <geometry>
        <mesh
          filename="package://rom2109_description/meshes/short/lidar.STL" />
      </geometry>
    </collision>
  </link>
  <joint
    name="lidar_joint"
    type="fixed">
    <origin
      xyz="0.0159981253913117 -0.00158018301594736 0.0325999999999998"
      rpy="0 0 0" />
    <parent
      link="plate1" />
    <child
      link="lidar" />
    <axis
      xyz="0 0 0" />
  </joint>

    <!--GAZEBO ADD BY ROM ROBOTICS-->
  
  <!-- here is the gazebo plug-in to simulate a lidar sensor -->
  <gazebo reference="lidar">
    <sensor type="ray" name="head_hokuyo_sensor">
    <!--sensor type="gpu_ray" name="sick_lidar_sensor"-->
      <pose>0 0 0 0 0 0</pose>
      <visualize>true</visualize>
      <update_rate>40</update_rate>
      <ray>
        <scan>
          <horizontal>
            <samples>720</samples>
            <resolution>1</resolution>
            <min_angle>-1.570796</min_angle>
            <max_angle>1.570796</max_angle>
          </horizontal>
        </scan>
        <range>
          <min>0.10</min>
          <max>30.0</max>
          <resolution>0.01</resolution>
        </range>
        <noise>
          <type>gaussian</type>
          <mean>0.0</mean>
          <stddev>0.01</stddev>
        </noise>
      </ray>
      <!--plugin name="gazebo_ros_lidar_controller" filename="libgazebo_ros_gpu_laser.so"-->
      <plugin name="gazebo_ros_head_hokuyo_controller" filename="libgazebo_ros_laser.so">
        <topicName>/scan</topicName>
        <frameName>lidar</frameName>
      </plugin>
    </sensor>
  </gazebo>  

<gazebo>
  <plugin name="gazebo_ros_control" filename="libgazebo_ros_contol.so">
  </plugin>
</gazebo>

 <!-- Colour -->
  <gazebo reference="base_link">
    <material>Gazebo/Black</material>
  </gazebo>

  <gazebo reference="plate1">
    <material>Gazebo/Yellow</material>
  </gazebo>

  <gazebo>
    <plugin name="differential_drive_controller" filename="libgazebo_ros_diff_drive.so">
      <alwaysOn>true</alwaysOn>
	    <updateRate>10.0</updateRate> 
		  <robotBaseFrame>base_link</robotBaseFrame>
		  <publishWheelTF>true</publishWheelTF>
		  <publishWheelJointState>true</publishWheelJointState>
		  <wheelAcceleration>1</wheelAcceleration>
		  <leftJoint>left_wheel_joint</leftJoint>
		  <rightJoint>right_wheel_joint</rightJoint>
		  <wheelSeparation>0.33</wheelSeparation>
		  <wheelDiameter>0.17</wheelDiameter>
		  <wheelTorque>20</wheelTorque>
		  <commandTopic>cmd_vel</commandTopic>
		  <odometryTopic>odom</odometryTopic>
		  <odometryFrame>odom</odometryFrame>
    </plugin>
 </gazebo> 

</robot>