<?xml version="1.0" encoding="utf-8"?>
<!-- This URDF was automatically created by SolidWorks to URDF Exporter! Originally created by Stephen Brawner (brawner@gmail.com) 
     Commit Version: 1.6.0-1-g15f4949  Build Version: 1.6.7594.29634
     For more information, please see http://wiki.ros.org/sw_urdf_exporter -->
<robot
  name="rom2109">
  <link
    name="base_link">
    <inertial>
      <origin
        xyz="0.0018801 0.00063186 0.013703"
        rpy="0 0 0" />
      <mass
        value="2.3926" />
      <inertia
        ixx="0.012278"
        ixy="5.4399E-06"
        ixz="2.5169E-07"
        iyy="0.01532"
        iyz="-7.22E-06"
        izz="0.024356" />
    </inertial>
    <visual>
      <origin
        xyz="0 0 0"
        rpy="0 0 0" />
      <geometry>
        <mesh
          filename="package://rom2109_description/meshes/tall/base_link.STL" />
      </geometry>
      <material
        name="">
        <color
          rgba="0 0 0 1" />
      </material>
    </visual>
    <collision>
      <origin
        xyz="0 0 0"
        rpy="0 0 0" />
      <geometry>
        <mesh
          filename="package://rom2109_description/meshes/tall/base_link.STL" />
      </geometry>
    </collision>
  </link>
  <link
    name="right_wheel">
    <inertial>
      <origin
        xyz="5.2042E-18 -0.0009488 1.1102E-16"
        rpy="0 0 0" />
      <mass
        value="2.8826" />
      <inertia
        ixx="0.0029015"
        ixy="8.8473E-19"
        ixz="1.0826E-19"
        iyy="0.00525"
        iyz="8.1336E-18"
        izz="0.0029015" />
    </inertial>
    <visual>
      <origin
        xyz="0 0 0"
        rpy="0 0 0" />
      <geometry>
        <mesh
          filename="package://rom2109_description/meshes/tall/right_wheel.STL" />
      </geometry>
      <material
        name="">
        <color
          rgba="0.79608 0.82353 0.93725 1" />
      </material>
    </visual>
    <collision>
      <origin
        xyz="0 0 0"
        rpy="0 0 0" />
      <geometry>
        <mesh
          filename="package://rom2109_description/meshes/tall/right_wheel.STL" />
      </geometry>
    </collision>
  </link>
  <joint
    name="right_wheel_joint"
    type="continuous">
    <origin
      xyz="0 -0.098333 0.02605"
      rpy="0 0 0" />
    <parent
      link="base_link" />
    <child
      link="right_wheel" />
    <axis
      xyz="0 1 0" />
  </joint>
  <link
    name="left_wheel">
    <inertial>
      <origin
        xyz="1.70261374443648E-13 0.000948803305975868 5.84532422465145E-14"
        rpy="0 0 0" />
      <mass
        value="2.88257784807586" />
      <inertia
        ixx="0.00290151800584146"
        ixy="-9.17143296382601E-15"
        ixz="6.05064629220322E-15"
        iyy="0.00524996334354856"
        iyz="-2.7078542422645E-15"
        izz="0.00290151800582675" />
    </inertial>
    <visual>
      <origin
        xyz="0 0 0"
        rpy="0 0 0" />
      <geometry>
        <mesh
          filename="package://rom2109_description/meshes/tall/left_wheel.STL" />
      </geometry>
      <material
        name="">
        <color
          rgba="0.796078431372549 0.823529411764706 0.937254901960784 1" />
      </material>
    </visual>
    <collision>
      <origin
        xyz="0 0 0"
        rpy="0 0 0" />
      <geometry>
        <mesh
          filename="package://rom2109_description/meshes/tall/left_wheel.STL" />
      </geometry>
    </collision>
  </link>
  <joint
    name="left_wheel_joint"
    type="continuous">
    <origin
      xyz="0 0.098333 0.02605"
      rpy="0 0 0" />
    <parent
      link="base_link" />
    <child
      link="left_wheel" />
    <axis
      xyz="0 1 0" />
  </joint>
  <link
    name="plate1">
    <inertial>
      <origin
        xyz="0.00237736961809817 -0.00318479486350609 0.0037769125523156"
        rpy="0 0 0" />
      <mass
        value="0.376303345586596" />
      <inertia
        ixx="0.00140681231884876"
        ixy="3.65375356586582E-05"
        ixz="1.48900919093625E-17"
        iyy="0.00141154373447315"
        iyz="-5.24274468346476E-18"
        izz="0.00281452124473489" />
    </inertial>
    <visual>
      <origin
        xyz="0 0 0"
        rpy="0 0 0" />
      <geometry>
        <mesh
          filename="package://rom2109_description/meshes/tall/plate1.STL" />
      </geometry>
      <material
        name="">
        <color
          rgba="1 1 0 1" />
      </material>
    </visual>
    <collision>
      <origin
        xyz="0 0 0"
        rpy="0 0 0" />
      <geometry>
        <mesh
          filename="package://rom2109_description/meshes/tall/plate1.STL" />
      </geometry>
    </collision>
  </link>
  <joint
    name="plate1_joint"
    type="fixed">
    <origin
      xyz="-0.0038733 0 0.15505"
      rpy="0 0 0" />
    <parent
      link="base_link" />
    <child
      link="plate1" />
    <axis
      xyz="0 0 0" />
  </joint>
  <link
    name="camera">
    <inertial>
      <origin
        xyz="-0.013048 -0.0002462 6.0567E-05"
        rpy="0 0 0" />
      <mass
        value="0.044752" />
      <inertia
        ixx="2.7278E-05"
        ixy="-2.4434E-07"
        ixz="1.174E-09"
        iyy="3.9447E-06"
        iyz="-2.8019E-09"
        izz="2.7362E-05" />
    </inertial>
    <visual>
      <origin
        xyz="0 0 0"
        rpy="0 0 0" />
      <geometry>
        <mesh
          filename="package://rom2109_description/meshes/tall/camera.STL" />
      </geometry>
      <material
        name="">
        <color
          rgba="0.79216 0.81961 0.93333 1" />
      </material>
    </visual>
    <collision>
      <origin
        xyz="0 0 0"
        rpy="0 0 0" />
      <geometry>
        <mesh
          filename="package://rom2109_description/meshes/tall/camera.STL" />
      </geometry>
    </collision>
  </link>
  <joint
    name="camera_joint"
    type="fixed">
    <origin
      xyz="0.1095 0.0055774 -0.0125"
      rpy="0 0 0" />
    <parent
      link="plate1" />
    <child
      link="camera" />
    <axis
      xyz="0 0 0" />
  </joint>
  <link
    name="lidar">
    <inertial>
      <origin
        xyz="-0.00745026268241726 -0.000710181573741274 0.0106681277328404"
        rpy="0 0 0" />
      <mass
        value="1.33076913637071" />
      <inertia
        ixx="0.000617412562574113"
        ixy="-2.92747154921629E-05"
        ixz="0.000157957059991761"
        iyy="0.000958202713497202"
        iyz="9.99903112863992E-06"
        izz="0.00109815200027136" />
    </inertial>
    <visual>
      <origin
        xyz="0 0 0"
        rpy="0 0 0" />
      <geometry>
        <mesh
          filename="package://rom2109_description/meshes/tall/lidar.STL" />
      </geometry>
      <material
        name="">
        <color
          rgba="0.792156862745098 0.819607843137255 0.933333333333333 1" />
      </material>
    </visual>
    <collision>
      <origin
        xyz="0 0 0"
        rpy="0 0 0" />
      <geometry>
        <mesh
          filename="package://rom2109_description/meshes/tall/lidar.STL" />
      </geometry>
    </collision>
  </link>
  <joint
    name="lidar_joint"
    type="fixed">
    <origin
      xyz="0.015998 -0.0015802 0.0326"
      rpy="0 0 0" />
    <parent
      link="plate1" />
    <child
      link="lidar" />
    <axis
      xyz="0 0 0" />
  </joint>
  <link
    name="plate2">
    <inertial>
      <origin
        xyz="6.2039E-05 5.5952E-05 0.004"
        rpy="0 0 0" />
      <mass
        value="0.35881" />
      <inertia
        ixx="0.0014023"
        ixy="3.6515E-05"
        ixz="1.454E-17"
        iyy="0.001401"
        iyz="-5.3509E-18"
        izz="0.0027995" />
    </inertial>
    <visual>
      <origin
        xyz="0 0 0"
        rpy="0 0 0" />
      <geometry>
        <mesh
          filename="package://rom2109_description/meshes/tall/plate2.STL" />
      </geometry>
      <material
        name="">
        <color
          rgba="1 1 0 1" />
      </material>
    </visual>
    <collision>
      <origin
        xyz="0 0 0"
        rpy="0 0 0" />
      <geometry>
        <mesh
          filename="package://rom2109_description/meshes/tall/plate2.STL" />
      </geometry>
    </collision>
  </link>
  <joint
    name="plate2_joint"
    type="fixed">
    <origin
      xyz="-0.0038733 0 0.2668"
      rpy="0 0 0" />
    <parent
      link="base_link" />
    <child
      link="plate2" />
    <axis
      xyz="0 0 0" />
  </joint>
  <link
    name="plate3">
    <inertial>
      <origin
        xyz="0 0 0"
        rpy="0 0 0" />
      <mass
        value="0" />
      <inertia
        ixx="0"
        ixy="0"
        ixz="0"
        iyy="0"
        iyz="0"
        izz="0" />
    </inertial>
    <visual>
      <origin
        xyz="0 0 0"
        rpy="0 0 0" />
      <geometry>
        <mesh
          filename="package://rom2109_description/meshes/tall/plate3.STL" />
      </geometry>
      <material
        name="">
        <color
          rgba="1 1 0 1" />
      </material>
    </visual>
    <collision>
      <origin
        xyz="0 0 0"
        rpy="0 0 0" />
      <geometry>
        <mesh
          filename="package://rom2109_description/meshes/tall/plate3.STL" />
      </geometry>
    </collision>
  </link>
  <joint
    name="plate3_joint"
    type="fixed">
    <origin
      xyz="-0.00387334814860704 0 0.424802362186551"
      rpy="0 0 0" />
    <parent
      link="base_link" />
    <child
      link="plate3" />
    <axis
      xyz="0 0 0" />
  </joint>
</robot>