<?xml version="1.0" encoding="utf-8"?>
<!-- This URDF was automatically created by SolidWorks to URDF Exporter! Originally created by Stephen Brawner (brawner@gmail.com) 
     Commit Version: 1.6.0-1-g15f4949  Build Version: 1.6.7594.29634
     For more information, please see http://wiki.ros.org/sw_urdf_exporter -->
<robot
  name="rom2109_description">
  <link
    name="base_link">
    <inertial>
      <origin
        xyz="0.017428 -0.00036384 0.019741"
        rpy="0 0 0" />
      <mass
        value="2.8573" />
      <inertia
        ixx="0.011264"
        ixy="-1.3804E-06"
        ixz="-1.3459E-07"
        iyy="0.015015"
        iyz="-7.3046E-07"
        izz="0.025902" />
    </inertial>
    <visual>
      <origin
        xyz="0 0 0"
        rpy="0 0 0" />
      <geometry>
        <mesh
          filename="model://rom2109_description/meshes/bot/base_link.STL" />
      </geometry>
      <material
        name="">
        <color
          rgba="0 0 0 1" />
      </material>
    </visual>
    <collision>
      <origin
        xyz="0 0 0"
        rpy="0 0 0" />
      <geometry>
        <mesh
          filename="model://rom2109_description/meshes/bot/base_link.STL" />
      </geometry>
    </collision>
  </link>

  <link
    name="left_wheel">
    <inertial>
      <origin
        xyz="1.1102E-16 4.3162E-05 1.3878E-16"
        rpy="0 0 0" />
      <mass
        value="2.8826" />
      <inertia
        ixx="0.0029015"
        ixy="-2.7371E-19"
        ixz="-1.4432E-19"
        iyy="0.00525"
        iyz="6.1539E-21"
        izz="0.0029015" />
    </inertial>
    <visual>
      <origin
        xyz="0 0 0"
        rpy="0 0 0" />
      <geometry>
        <mesh
          filename="model://rom2109_description/meshes/bot/left_wheel.STL" />
      </geometry>
      <material
        name="">
        <color
          rgba="0.29804 0.29804 0.29804 1" />
      </material>
    </visual>
    <collision>
      <origin
        xyz="0 0 0"
        rpy="0 0 0" />
      <geometry>
        <mesh
          filename="model://rom2109_description/meshes/bot/left_wheel.STL" />
      </geometry>
    </collision>
  </link>
  <joint
    name="left_wheel_joint"
    type="continuous">
    <origin
      xyz="0 0.098333 0.02605"
      rpy="0 0 0" />
    <parent
      link="base_link" />
    <child
      link="left_wheel" />
    <axis
      xyz="0 1 0" />
  </joint>
  <link
    name="right_wheel">
    <inertial>
      <origin
        xyz="0 4.3162E-05 -1.3878E-16"
        rpy="0 0 0" />
      <mass
        value="2.8826" />
      <inertia
        ixx="0.0029015"
        ixy="1.8806E-19"
        ixz="-1.5661E-19"
        iyy="0.00525"
        iyz="9.7374E-20"
        izz="0.0029015" />
    </inertial>
    <visual>
      <origin
        xyz="0 0 0"
        rpy="0 0 0" />
      <geometry>
        <mesh
          filename="model://rom2109_description/meshes/bot/right_wheel.STL" />
      </geometry>
      <material
        name="">
        <color
          rgba="0.29804 0.29804 0.29804 1" />
      </material>
    </visual>
    <collision>
      <origin
        xyz="0 0 0"
        rpy="0 0 0" />
      <geometry>
        <mesh
          filename="model://rom2109_description/meshes/bot/right_wheel.STL" />
      </geometry>
    </collision>
  </link>
  <joint
    name="right_wheel_joint"
    type="continuous">
    <origin
      xyz="0 -0.098333 0.02605"
      rpy="0 0 0" />
    <parent
      link="base_link" />
    <child
      link="right_wheel" />
    <axis
      xyz="0 1 0" />
  </joint>
  <link
    name="rp_lidar">
    <inertial>
      <origin
        xyz="0.0067664 -0.00010084 -0.022432"
        rpy="0 0 0" />
      <mass
        value="0.17402" />
      <inertia
        ixx="8.0412E-05"
        ixy="-4.5283E-08"
        ixz="2.0693E-05"
        iyy="0.00012563"
        iyz="-4.3156E-07"
        izz="0.0001436" />
    </inertial>
    <visual>
      <origin
        xyz="0 0 0"
        rpy="0 0 0" />
      <geometry>
        <mesh
          filename="model://rom2109_description/meshes/bot/rp_lidar.STL" />
      </geometry>
      <material
        name="">
        <color
          rgba="0.1 0.1 0.1 1" />
      </material>
    </visual>
    <collision>
      <origin
        xyz="0 0 0"
        rpy="0 0 0" />
      <geometry>
        <mesh
          filename="model://rom2109_description/meshes/bot/rp_lidar.STL" />
      </geometry>
    </collision>
  </link>
  <joint
    name="rp_lidar_joint"
    type="fixed">
    <origin
      xyz="-0.016132 -3.6141E-05 0.20083"
      rpy="0 0 0" />
    <parent
      link="base_link" />
    <child
      link="rp_lidar" />
    <axis
      xyz="0 0 0" />
  </joint>
  <link
    name="frame_link">
    <inertial>
      <origin
        xyz="-0.0070676 -3.6814E-05 0.11019"
        rpy="0 0 0" />
      <mass
        value="2.3643" />
      <inertia
        ixx="0.016744"
        ixy="4.303E-07"
        ixz="0.00012055"
        iyy="0.0074688"
        iyz="2.3796E-06"
        izz="0.017437" />
    </inertial>
    <visual>
      <origin
        xyz="0 0 0"
        rpy="0 0 0" />
      <geometry>
        <mesh
          filename="model://rom2109_description/meshes/bot/frame_link.STL" />
      </geometry>
      <material
        name="">
        <color
          rgba="1 1 0.50196 1" />
      </material>
    </visual>
    <collision>
      <origin
        xyz="0 0 0"
        rpy="0 0 0" />
      <geometry>
        <mesh
          filename="model://rom2109_description/meshes/bot/frame_link.STL" />
      </geometry>
    </collision>
  </link>
  <joint
    name="frame_joint"
    type="fixed">
    <origin
      xyz="0 0 0"
      rpy="0 0 0" />
    <parent
      link="base_link" />
    <child
      link="frame_link" />
    <axis
      xyz="0 0 0" />
  </joint>
  <link
    name="wifi">
    <inertial>
      <origin
        xyz="-0.11391 0.00050098 0.059664"
        rpy="0 0 0" />
      <mass
        value="0.46643" />
      <inertia
        ixx="0.0014606"
        ixy="-9.2975E-12"
        ixz="6.678E-05"
        iyy="0.00061425"
        iyz="4.7514E-10"
        izz="0.00093003" />
    </inertial>
    <visual>
      <origin
        xyz="0 0 0"
        rpy="0 0 0" />
      <geometry>
        <mesh
          filename="model://rom2109_description/meshes/bot/wifi.STL" />
      </geometry>
      <material
        name="">
        <color
          rgba="0.1 0.1 0.1 1" />
      </material>
    </visual>
    <collision>
      <origin
        xyz="0 0 0"
        rpy="0 0 0" />
      <geometry>
        <mesh
          filename="model://rom2109_description/meshes/bot/wifi.STL" />
      </geometry>
    </collision>
  </link>
  <joint
    name="wifi_joint"
    type="fixed">
    <origin
      xyz="0 0 0"
      rpy="0 0 0" />
    <parent
      link="base_link" />
    <child
      link="wifi" />
    <axis
      xyz="0 0 0" />
  </joint>
      <!--GAZEBO ADD BY ROM ROBOTICS-->
  
  <!-- here is the gazebo plug-in to simulate a lidar sensor -->
  <gazebo reference="rp_lidar">
    <sensor type="ray" name="head_hokuyo_sensor">
    <!--sensor type="gpu_ray" name="sick_lidar_sensor"-->
      <pose>0 0 0 0 0 0</pose>
      <visualize>true</visualize>
      <update_rate>40</update_rate>
      <ray>
        <scan>
          <horizontal>
            <samples>720</samples>
            <resolution>1</resolution>
            <min_angle>-1.570796</min_angle>
            <max_angle>1.570796</max_angle>
          </horizontal>
        </scan>
        <range>
          <min>0.10</min>
          <max>30.0</max>
          <resolution>0.01</resolution>
        </range>
        <noise>
          <type>gaussian</type>
          <mean>0.0</mean>
          <stddev>0.01</stddev>
        </noise>
      </ray>
      <!--plugin name="gazebo_ros_lidar_controller" filename="libgazebo_ros_gpu_laser.so"-->
      <plugin name="gazebo_ros_head_hokuyo_controller" filename="libgazebo_ros_laser.so">
        <topicName>/scan</topicName>
        <frameName>rp_lidar</frameName>
      </plugin>
    </sensor>
  </gazebo>  

<gazebo>
  <plugin name="gazebo_ros_control" filename="libgazebo_ros_contol.so">
  </plugin>
</gazebo>

 <!-- Colour -->
  <gazebo reference="base_link">
    <material>Gazebo/Black</material>
  </gazebo>

  <gazebo reference="frame_link">
    <material>Gazebo/Yellow</material>
  </gazebo>

  <gazebo>
    <plugin name="differential_drive_controller" filename="libgazebo_ros_diff_drive.so">
      <alwaysOn>true</alwaysOn>
	    <updateRate>10.0</updateRate> 
		  <robotBaseFrame>base_link</robotBaseFrame>
		  <publishWheelTF>true</publishWheelTF>
		  <publishWheelJointState>true</publishWheelJointState>
		  <wheelAcceleration>1</wheelAcceleration>
		  <leftJoint>left_wheel_joint</leftJoint>
		  <rightJoint>right_wheel_joint</rightJoint>
		  <wheelSeparation>0.33</wheelSeparation>
		  <wheelDiameter>0.17</wheelDiameter>
		  <wheelTorque>20</wheelTorque>
		  <commandTopic>cmd_vel</commandTopic>
		  <odometryTopic>odom</odometryTopic>
		  <odometryFrame>odom</odometryFrame>
    </plugin>
 </gazebo> 

</robot>