<?xml version="1.0" ?>
<!-- =================================================================================== -->
<!-- |    This document was autogenerated by xacro from robot_sim_ros2_control.urdf.xacro | -->
<!-- |    EDITING THIS FILE BY HAND IS NOT RECOMMENDED                                 | -->
<!-- =================================================================================== -->
<robot name="rom2109">
  <link name="base_footprint"/>
  <joint name="base_footprint_joint" type="fixed">
    <parent link="base_footprint"/>
    <child link="base_link"/>
    <origin rpy="0 0 0" xyz="0 0 0"/>
  </joint>
  <link name="base_link">
    <inertial>
      <origin rpy="0 0 0" xyz="0.0018801 0.00063186 0.013703"/>
      <mass value="2.3926"/>
      <inertia ixx="0.012278" ixy="5.4399E-06" ixz="2.5169E-07" iyy="0.01532" iyz="-7.22E-06" izz="0.024356"/>
    </inertial>
    <visual>
      <origin rpy="0 0 0" xyz="0 0 0"/>
      <geometry>
        <mesh filename="/home/zyme/.gazebo/models/rom2109_tall/meshes/tall/base_link.STL"/>
      </geometry>
      <material name="">
        <color rgba="0 0 0 1"/>
      </material>
    </visual>
    <collision>
      <origin rpy="0 0 0" xyz="0 0 0"/>
      <geometry>
        <mesh filename="/home/zyme/.gazebo/models/rom2109_tall/meshes/tall/base_link.STL"/>
      </geometry>
    </collision>
  </link>
  <link name="right_wheel">
    <inertial>
      <origin rpy="0 0 0" xyz="5.2042E-18 -0.0009488 1.1102E-16"/>
      <mass value="2.8826"/>
      <inertia ixx="0.0029015" ixy="8.8473E-19" ixz="1.0826E-19" iyy="0.00525" iyz="8.1336E-18" izz="0.0029015"/>
    </inertial>
    <visual>
      <origin rpy="0 0 0" xyz="0 0 0"/>
      <geometry>
        <mesh filename="/home/zyme/.gazebo/models/rom2109_tall/meshes/tall/right_wheel.STL"/>
      </geometry>
      <material name="">
        <color rgba="0.79608 0.82353 0.93725 1"/>
      </material>
    </visual>
    <collision>
      <origin rpy="0 0 0" xyz="0 0 0"/>
      <geometry>
        <mesh filename="/home/zyme/.gazebo/models/rom2109_tall/meshes/tall/right_wheel.STL"/>
      </geometry>
    </collision>
  </link>
  <joint name="right_wheel_joint" type="continuous">
    <origin rpy="0 0 0" xyz="0 -0.098333 0.02605"/>
    <parent link="base_link"/>
    <child link="right_wheel"/>
    <axis xyz="0 1 0"/>
  </joint>
  <link name="left_wheel">
    <inertial>
      <origin rpy="0 0 0" xyz="1.70261374443648E-13 0.000948803305975868 5.84532422465145E-14"/>
      <mass value="2.88257784807586"/>
      <inertia ixx="0.00290151800584146" ixy="-9.17143296382601E-15" ixz="6.05064629220322E-15" iyy="0.00524996334354856" iyz="-2.7078542422645E-15" izz="0.00290151800582675"/>
    </inertial>
    <visual>
      <origin rpy="0 0 0" xyz="0 0 0"/>
      <geometry>
        <mesh filename="/home/zyme/.gazebo/models/rom2109_tall/meshes/tall/left_wheel.STL"/>
      </geometry>
      <material name="">
        <color rgba="0.796078431372549 0.823529411764706 0.937254901960784 1"/>
      </material>
    </visual>
    <collision>
      <origin rpy="0 0 0" xyz="0 0 0"/>
      <geometry>
        <mesh filename="/home/zyme/.gazebo/models/rom2109_tall/meshes/tall/left_wheel.STL"/>
      </geometry>
    </collision>
  </link>
  <joint name="left_wheel_joint" type="continuous">
    <origin rpy="0 0 0" xyz="0 0.098333 0.02605"/>
    <parent link="base_link"/>
    <child link="left_wheel"/>
    <axis xyz="0 1 0"/>
  </joint>
  <link name="plate1">
    <inertial>
      <origin rpy="0 0 0" xyz="0.00237736961809817 -0.00318479486350609 0.0037769125523156"/>
      <mass value="0.376303345586596"/>
      <inertia ixx="0.00140681231884876" ixy="3.65375356586582E-05" ixz="1.48900919093625E-17" iyy="0.00141154373447315" iyz="-5.24274468346476E-18" izz="0.00281452124473489"/>
    </inertial>
    <visual>
      <origin rpy="0 0 0" xyz="0 0 0"/>
      <geometry>
        <mesh filename="/home/zyme/.gazebo/models/rom2109_tall/meshes/tall/plate1.STL"/>
      </geometry>
      <material name="">
        <color rgba="1 1 0 1"/>
      </material>
    </visual>
    <collision>
      <origin rpy="0 0 0" xyz="0 0 0"/>
      <geometry>
        <mesh filename="/home/zyme/.gazebo/models/rom2109_tall/meshes/tall/plate1.STL"/>
      </geometry>
    </collision>
  </link>
  <joint name="plate1_joint" type="fixed">
    <origin rpy="0 0 0" xyz="-0.0038733 0 0.15505"/>
    <parent link="base_link"/>
    <child link="plate1"/>
    <axis xyz="0 0 0"/>
  </joint>
  <link name="camera">
    <inertial>
      <origin rpy="0 0 0" xyz="-0.013048 -0.0002462 6.0567E-05"/>
      <mass value="0.044752"/>
      <inertia ixx="2.7278E-05" ixy="-2.4434E-07" ixz="1.174E-09" iyy="3.9447E-06" iyz="-2.8019E-09" izz="2.7362E-05"/>
    </inertial>
    <visual>
      <origin rpy="0 0 0" xyz="0 0 0"/>
      <geometry>
        <mesh filename="/home/zyme/.gazebo/models/rom2109_tall/meshes/tall/camera.STL"/>
      </geometry>
      <material name="">
        <color rgba="0.79216 0.81961 0.93333 1"/>
      </material>
    </visual>
    <collision>
      <origin rpy="0 0 0" xyz="0 0 0"/>
      <geometry>
        <mesh filename="/home/zyme/.gazebo/models/rom2109_tall/meshes/tall/camera.STL"/>
      </geometry>
    </collision>
  </link>
  <joint name="camera_joint" type="fixed">
    <origin rpy="0 0 0" xyz="0.1095 0.0055774 -0.0125"/>
    <parent link="plate1"/>
    <child link="camera"/>
    <axis xyz="0 0 0"/>
  </joint>
  <link name="lidar">
    <inertial>
      <origin rpy="0 0 0" xyz="-0.00745026268241726 -0.000710181573741274 0.0106681277328404"/>
      <mass value="1.33076913637071"/>
      <inertia ixx="0.000617412562574113" ixy="-2.92747154921629E-05" ixz="0.000157957059991761" iyy="0.000958202713497202" iyz="9.99903112863992E-06" izz="0.00109815200027136"/>
    </inertial>
    <visual>
      <origin rpy="0 0 0" xyz="0 0 0"/>
      <geometry>
        <mesh filename="/home/zyme/.gazebo/models/rom2109_tall/meshes/tall/lidar.STL"/>
      </geometry>
      <material name="">
        <color rgba="0.792156862745098 0.819607843137255 0.933333333333333 1"/>
      </material>
    </visual>
    <collision>
      <origin rpy="0 0 0" xyz="0 0 0"/>
      <geometry>
        <mesh filename="/home/zyme/.gazebo/models/rom2109_tall/meshes/tall/lidar.STL"/>
      </geometry>
    </collision>
  </link>
  <joint name="lidar_joint" type="fixed">
    <origin rpy="0 0 0" xyz="0.015998 -0.0015802 0.0326"/>
    <parent link="plate1"/>
    <child link="lidar"/>
    <axis xyz="0 0 0"/>
  </joint>
  <link name="plate2">
    <inertial>
      <origin rpy="0 0 0" xyz="6.2039E-05 5.5952E-05 0.004"/>
      <mass value="0.35881"/>
      <inertia ixx="0.0014023" ixy="3.6515E-05" ixz="1.454E-17" iyy="0.001401" iyz="-5.3509E-18" izz="0.0027995"/>
    </inertial>
    <visual>
      <origin rpy="0 0 0" xyz="0 0 0"/>
      <geometry>
        <mesh filename="/home/zyme/.gazebo/models/rom2109_tall/meshes/tall/plate2.STL"/>
      </geometry>
      <material name="">
        <color rgba="1 1 0 1"/>
      </material>
    </visual>
    <collision>
      <origin rpy="0 0 0" xyz="0 0 0"/>
      <geometry>
        <mesh filename="/home/zyme/.gazebo/models/rom2109_tall/meshes/tall/plate2.STL"/>
      </geometry>
    </collision>
  </link>
  <joint name="plate2_joint" type="fixed">
    <origin rpy="0 0 0" xyz="-0.0038733 0 0.2668"/>
    <parent link="base_link"/>
    <child link="plate2"/>
    <axis xyz="0 0 0"/>
  </joint>
  <link name="plate3">
    <inertial>
      <origin rpy="0 0 0" xyz="0 0 0"/>
      <mass value="0"/>
      <inertia ixx="0" ixy="0" ixz="0" iyy="0" iyz="0" izz="0"/>
    </inertial>
    <visual>
      <origin rpy="0 0 0" xyz="0 0 0"/>
      <geometry>
        <mesh filename="/home/zyme/.gazebo/models/rom2109_tall/meshes/tall/plate3.STL"/>
      </geometry>
      <material name="">
        <color rgba="1 1 0 1"/>
      </material>
    </visual>
    <collision>
      <origin rpy="0 0 0" xyz="0 0 0"/>
      <geometry>
        <mesh filename="/home/zyme/.gazebo/models/rom2109_tall/meshes/tall/plate3.STL"/>
      </geometry>
    </collision>
  </link>
  <joint name="plate3_joint" type="fixed">
    <origin rpy="0 0 0" xyz="-0.00387334814860704 0 0.424802362186551"/>
    <parent link="base_link"/>
    <child link="plate3"/>
    <axis xyz="0 0 0"/>
  </joint>
  <!-- Colour -->
  <gazebo reference="base_link">
    <material>Gazebo/Black</material>
  </gazebo>
  <gazebo reference="plate1">
    <material>Gazebo/Yellow</material>
  </gazebo>
  <gazebo reference="plate2">
    <material>Gazebo/Yellow</material>
  </gazebo>
  <gazebo reference="plate3">
    <material>Gazebo/Yellow</material>
  </gazebo>
  <gazebo reference="lidar">
    <material>Gazebo/Red</material>
    <sensor name="laser" type="ray">
      <pose>0 0 0 0 0 0</pose>
      <visualize>false</visualize>
      <update_rate>10</update_rate>
      <ray>
        <scan>
          <horizontal>
            <samples>360</samples>
            <resolution>1</resolution>
            <min_angle>-3.14</min_angle>
            <max_angle>3.14</max_angle>
          </horizontal>
        </scan>
        <range>
          <min>0.3</min>
          <max>12</max>
          <resolution>0.01</resolution>
        </range>
      </ray>
      <plugin filename="libgazebo_ros_ray_sensor.so" name="laser_controller">
        <ros>
          <argument>~/out:=scan</argument>
        </ros>
        <output_type>sensor_msgs/LaserScan</output_type>
        <frame_name>lidar</frame_name>
      </plugin>
    </sensor>
  </gazebo>
  <ros2_control name="GazeboSystem" type="system">
    <hardware>
      <plugin>gazebo_ros2_control/GazeboSystem</plugin>
    </hardware>
    <joint name="left_wheel_joint">
      <command_interface name="velocity">
        <param name="min">-10</param>
        <param name="max">10</param>
      </command_interface>
      <state_interface name="velocity"/>
      <state_interface name="position"/>
    </joint>
    <joint name="right_wheel_joint">
      <command_interface name="velocity">
        <param name="min">-10</param>
        <param name="max">10</param>
      </command_interface>
      <state_interface name="velocity"/>
      <state_interface name="position"/>
    </joint>
  </ros2_control>
  <gazebo>
    <plugin filename="libgazebo_ros2_control.so" name="gazebo_ros2_control">
      <robot_param>robot_description</robot_param>
      <robot_param_node>robot_state_publisher</robot_param_node>
      <parameters>~/ros_ws/rom2109_simulation/install/rom2109_description/share/rom2109_description/config/my_controllers.yaml</parameters>
      <!-- Output -->
      <odometry_frame>odom</odometry_frame>
      <robot_base_frame>base_footprint</robot_base_frame>
      <publish_odom>true</publish_odom>
      <publish_odom_tf>true</publish_odom_tf>
      <publish_wheel_tf>true</publish_wheel_tf>
    </plugin>
  </gazebo>
  <!-- <xacro:include filename="gazebo_control.xacro" /> -->
  <joint name="camera_optical_joint" type="fixed">
    <parent link="camera"/>
    <child link="camera_link_optical"/>
    <origin rpy="-1.5707963267948966 0 -1.5707963267948966" xyz="0 0 0"/>
  </joint>
  <link name="camera_link_optical"/>
  <gazebo reference="camera">
    <material>Gazebo/Blue</material>
    <sensor name="camera" type="camera">
      <pose>0 0 0 0 0 0</pose>
      <visualize>true</visualize>
      <update_rate>10</update_rate>
      <camera>
        <horizontal_fov>1.089</horizontal_fov>
        <image>
          <format>R8G8B8</format>
          <width>640</width>
          <height>480</height>
        </image>
        <clip>
          <near>0.05</near>
          <far>8.0</far>
        </clip>
      </camera>
      <plugin filename="libgazebo_ros_camera.so" name="camera_controller">
        <frame_name>camera_link_optical</frame_name>
      </plugin>
    </sensor>
  </gazebo>
  <!-- <xacro:include filename="camera3d.xacro" /> -->
</robot>
